<?xml version="1.0" ?>
<robot name="rb1_robot">

    <!-- Define materials for visualization -->
    <material name="blue">
        <color rgba="0 0 1 1"/>
    </material>

    <material name="gray">
        <color rgba="0.40 0.40 0.40 1"/>
    </material>

    <material name="red">
        <color rgba="1 0 0 1"/>
    </material>

    <!-- Base footprint link -->
    <link name="base_footprint">
    </link>

    <!-- Joint connecting base_link and base_footprint -->
    <!-- TO DO: Set correct joint type -->
    <joint name="base_link_plate_joint" type="fixed">
        <!-- TO DO: Define axis (if needed) -->
        <!-- TO DO: Define origin -->
        <origin xyz="0 0 0" rpy = "0 0 0"/>
        <!-- TO DO: Define parent -->
        <parent link="base_link"/>
        <!-- TO DO: Define child -->
        <child link="base_footprint"/>
    </joint>

    <!-- Base link -->
    <link name="base_link">
        
        <visual>
            <geometry>
                <cylinder radius =".25" height =".30"/>
            </geometry>
            <material name="blue"/>       
        </visual>
        <collision>
        <geometry>
            <cylinder radius =".25" height =".30"/>
        </geometry>
        </collision>   
        <inertial>
            <mass value="25" />
            <origin xyz="0 0 0.3" rpy="0 0 0" />
            <inertia ixx="0.578125" ixy="0" ixz="0" iyy="0.578125" iyz="0" izz="0.78125" />
        </inertial>

        
    </link>

    <!-- Left wheel link -->
    <link name="left_wheel">
        <!-- TO DO: Add visual tag -->
        <!-- TO DO: Add collision tag -->
        <!-- TO DO: Add inertial tag -->
            
        <visual>
        <geometry>
            <cylinder radius =".025" height =".01"/>
        </geometry>
        <material name="red"/>       
        </visual>
        <collision>
        <geometry>
            <cylinder radius =".025" height =".010"/>
        </geometry>
        </collision>   
        <inertial>
            <mass value="2.5" />
            <origin xyz="0 0 0" rpy="0 0 0" />
            <inertia ixx="0.00091" ixy="0" ixz="0" iyy="0.00091" iyz="0" izz="0.00078125" />
        </inertial>
    </link>

    <!-- Joint connecting base_link and left_wheel -->
    <!-- TO DO: Set correct joint type -->
    <joint name="base_link_left_wheel_joint" type="continuous">
        <!-- TO DO: Define axis (if needed) -->
        <!-- TO DO: Define origin -->
        <!-- TO DO: Define parent -->
        <!-- TO DO: Define child -->
        <origin xyz="0.3005 0 -0.1" rpy="0 0 0" />
        <child link="left_wheel" />
        <parent link="link_chassis" />
        <axis rpy="0 0 0" xyz="0 1 0" />
        <limit effort="10000" velocity="1000" />
        <joint_properties damping="1.0" friction="1.0" />
    </joint>

</robot>


<!--

<?xml version="1.0" ?>

<robot name="robot">
    <!-- Link - chassis -->
    <link name="link_chassis">
        <inertial>
            <mass value="10" />
            <origin xyz="0 0 0.3" rpy="0 0 0" />
            <inertia ixx="1.5417" ixy="0" ixz="0" iyy="3.467" iyz="0" izz="4.742" />
        </inertial>

        <collision>
            <geometry>
                <box size="2 1.3 0.4" />
            </geometry>
        </collision>

        <visual>
            <geometry>
                <box size="2 1.3 0.4" />
            </geometry>
            <material name="Red">
                <color rgba="1 0 0 1" />
            </material>
        </visual>
    </link>
</robot>

-->