<?xml version="1.0" ?>
<robot name="rb1_robot">


   <!-- Define materials for visualization -->
   <material name="blue">
       <color rgba="0 0 1 1"/>
   </material>


   <material name="gray">
       <color rgba="0.40 0.40 0.40 1"/>
   </material>


   <material name="red">
       <color rgba="1 0 0 1"/>
   </material>


   <!-- Base footprint link -->
   <link name="base_footprint">
   </link>


   <!-- Joint connecting base_link and base_footprint -->
   <!-- TO DO: Set correct joint type -->
   <joint name="base_link_plate_joint" type="fixed">
       <!-- TO DO: Define axis (if needed) -->
       <axis xyz="0 0 0"/>
       <origin xyz="0 0 -0.15" rpy = "0 0 0"/>
       <parent link="base_link"/>
       <child link="base_footprint"/>
   </joint>


   <!-- Base link -->
   <link name="base_link">
      
       <visual>
           <geometry>
               <cylinder radius ="0.25" length ="0.30"/>
           </geometry>
           <material name="blue"/>      
       </visual>
       <collision>
       <geometry>
           <cylinder radius =".25" length =".30"/>
       </geometry>
       </collision>  
       <inertial>
           <mass value="16" />
           <origin xyz="0 0 0.3" rpy="0 0 0" />
           <inertia ixx="0.65" ixy="0" ixz="0" iyy="0.65" iyz="0" izz="0.5" />
       </inertial>


   </link>


   <!-- Left wheel link -->
   <link name="left_wheel">           
       <visual>
       <geometry>
           <cylinder radius =".025" length =".020"/>
       </geometry>
       <material name="red"/>      
       </visual>
       <collision>
       <geometry>
           <cylinder radius =".025" length =".020"/>
       </geometry>
       </collision>  
       <inertial>
           <mass value="3" />
           <origin xyz="0 0 0" rpy="0 0 0" />
           <inertia ixx="0.00546875" ixy="0" ixz="0" iyy="0.00546875" iyz="0" izz="0.0009375" />
       </inertial>
   </link>


   <!-- Joint connecting base_link and left_wheel -->
   <!-- TO DO: Set correct joint type --> <!--0.3005 0 -0.1-->
   <joint name="base_link_left_wheel_joint" type="continuous">
       <origin xyz="0 -0.2 -0.15" rpy="1.57 0 0 " />
       <child link="left_wheel" />
       <parent link="base_link" />
       <axis rpy="0 0 0" xyz="0 0 1" />
       <limit effort="10000" velocity="1000" />
       <joint_properties damping="1.0" friction="0.2" />
   </joint>


   <!-- Right wheel link -->
   <link name="right_wheel">
        <visual>
       <geometry>
           <cylinder radius =".025" length =".020"/>
       </geometry>
       <material name="red"/>      
       </visual>
       <collision>
       <geometry>
           <cylinder radius =".025" length =".020"/>
       </geometry>
       </collision>  
       <inertial>
           <mass value="3" />
           <origin xyz="0 0 0" rpy="0 0 0" />
           <inertia ixx="0.00546875" ixy="0" ixz="0" iyy="0.00546875" iyz="0" izz="0.0009375" />
       </inertial>
   </link>


   <!-- Joint connecting base_link and right_wheel -->
   <!-- TO DO: Set correct joint type -->
   <joint name="base_link_right_wheel_joint" type="continuous">
       <origin xyz="0 0.2 -0.15" rpy="1.57 0 0 " />
       <child link="right_wheel" />
       <parent link="base_link" />
       <axis rpy="0 0 0" xyz="0 0 1" />
       <limit effort="10000" velocity="1000" />
       <joint_properties damping="1.0" friction="0.2" />
   </joint>


   <!-- Front caster -->
   <link name="front_caster">
       <visual>
       <geometry>
           <sphere radius =".025"/>
       </geometry>
       <material name="gray"/>      
       </visual>
       <collision>
       <geometry>
           <sphere radius =".025"/>
       </geometry>
       </collision>  
       <inertial>
           <mass value="1" />
           <origin xyz="0 0 0" rpy="0 0 0" />
           <inertia ixx="0.00025" ixy="0" ixz="0" iyy="0.00025" iyz="0" izz="0.00025" />
       </inertial>
   </link>




   <!-- Joint connecting base_link and front_caster -->


   <joint name="base_link_front_caster_joint" type="fixed">
       <origin xyz="0.1 0 -0.15" rpy="1.57 0 0 " />
       <child link="front_caster" />
       <parent link="base_link" />
       <axis rpy="0 0 0" xyz="0 0 0" />
       <limit effort="10000" velocity="1000" />
       <joint_properties damping="0" friction="0" />
   </joint>




   <!-- Back caster -->
   <link name="back_caster">
       <visual>
       <geometry>
           <sphere radius =".025"/>
       </geometry>
       <material name="gray"/>      
       </visual>
       <collision>
       <geometry>
           <sphere radius =".025" />
       </geometry>
       </collision>  
       <inertial>
           <mass value="1" />
           <origin xyz="0 0 0" rpy="0 0 0" />
           <inertia ixx="0.00025" ixy="0" ixz="0" iyy="0.00025" iyz="0" izz="0.00025" />
       </inertial>
   </link>




   <!-- Joint connecting base_link and front_caster -->


   <joint name="base_link_back_caster_joint" type="fixed">
       <origin xyz="-0.1 0 -0.15" rpy="1.57 0 0 " />
       <child link="back_caster" />
       <parent link="base_link" />
       <axis rpy="0 0 0" xyz="0 1 0" />
       <limit effort="10000" velocity="1000" />
       <joint_properties damping="0" friction="0" />
   </joint>


   <!-- Link representing the front laser scanner -->
   <!--For this robot, the laser is not visible, so we won't define a body for it. -->
   <link name="front_laser">
       <inertial>
           <mass value="1" />
           <origin xyz="0 0 0" rpy="0 0 0" />
           <inertia ixx="0.00091" ixy="0" ixz="0" iyy="0.00091" iyz="0" izz="0.00078125" />
       </inertial>
   </link>


   <!-- Joint connecting base_link and front_laser -->
   <!-- TO DO: Set correct joint type -->
   <joint name="base_link_front_laser_joint" type="fixed">
       <origin xyz="0.25 0 0.075" rpy="3.14 0 0 " />
       <child link="front_laser" />
       <parent link="base_link" />
       <joint_properties damping="1.0" friction="1.0" />
   </joint>


   <!-- Gazebo visualization -->
<gazebo reference="base_link">
    <material>Gazebo/Black</material>
</gazebo>

<gazebo reference="left_wheel">
    <material>Gazebo/Red</material>
    <mu1>1.0</mu1>
    <mu2>1.0</mu2>
    
    
</gazebo>

<gazebo reference="right_wheel">
    <material>Gazebo/Red</material>
    <mu1>1.0</mu1>
    <mu2>1.0</mu2>
    
</gazebo>

<gazebo reference="front_caster">
    <material>Gazebo/Orange</material>
    <mu1>0</mu1>
    <mu2>0</mu2>
    
</gazebo>

<gazebo reference="back_caster">
    <material>Gazebo/Orange</material>
    <mu1>0</mu1>
    <mu2>0</mu2>
    
</gazebo>

<gazebo reference="base_link_front_laser_joint">
    <preserveFixedJoint>true</preserveFixedJoint>
</gazebo>

    

<!--Gazebo Plugins-->
<gazebo>
    <plugin filename="libgazebo_ros_diff_drive.so" name="differential_drive_controller">
        <alwaysOn>true</alwaysOn>
        <updateRate>20</updateRate>
        <leftJoint>base_link_left_wheel_joint</leftJoint>
        <rightJoint>base_link_right_wheel_joint</rightJoint>
        <wheelSeparation>0.41</wheelSeparation>
        <wheelDiameter>0.05</wheelDiameter>
        <torque>10</torque>
        <commandTopic>cmd_vel</commandTopic>
        <odometryTopic>odom</odometryTopic>
        <odometryFrame>odom</odometryFrame>
        <robotBaseFrame>base_link</robotBaseFrame>
        <publishWheelJointState>true</publishWheelJointState>
        <publish_odom>true</publish_odom>
        <publish_odom_tf>true </publish_odom_tf>
        <publish_wheel_tf>true</publish_wheel_tf>
        
    </plugin>
</gazebo>

<gazebo reference="front_laser">
    <sensor type="ray" name="head_hokuyo_sensor">
        <pose>0 0 0 0 0 0</pose>
        <visualize>false</visualize>
        <update_rate>20</update_rate>
        <ray>
            <scan>
                <horizontal>
                    <samples>720</samples>
                    <resolution>1</resolution>
                    <min_angle>-1.570796</min_angle>
                    <max_angle>1.570796</max_angle>
                </horizontal>
            </scan>
            <range>
                <min>0.20</min>
                <max>10.0</max>
                <resolution>0.01</resolution>
            </range>
            <noise>
                <type>gaussian</type>
                <mean>0.0</mean>
                <stddev>0.01</stddev>
            </noise>
        </ray>
        <plugin name="gazebo_ros_head_hokuyo_controller" filename="libgazebo_ros_laser.so">
            <topicName>/scan</topicName>
            <frameName>sensor_laser</frameName>
        </plugin>
    </sensor>
</gazebo>

   </robot>

